Workbook

Sheet Daily Returns
A1: Date | B1: TELUS | C1: VERIZON | D1: ROGERS | E1: PEPSICO | F1: COCA-COLA | G1: JOHNSON&JOHNSON | H1: PROCTOR&GAMBLE | I1: ENBRIDGE | J1: FORTIS | K1: TD | L1: RBC | M1: MANULIFE | N1: SUNLIFE | O1: RESMED | P1: NEWMONT | Q1: BARRICK GOLD | R1: FREEPORT MCMORAN | S1: WHEATON PRECIOUS | T1: NUCOR CORP | U1: WASTE CONNECTIONS | V1: ICG | W1: ANGLO AMERICAN PLC | X1: Al Rajhi Banking & Investment Corp | Y1: CANADIAN NATL RAILWAY CO | Z1: CANADIAN PACIFIC KANSAS CITY LTD | AA1: EMERA INC | AB1: Great-West Lifeco Inc | AC1: Riyadh Cement Co. | AD1: Saudi Telecom | AE1: TMX GROUP LTD | AF1: WEIR GROUP | AG1: CVS Health Corp Bond | AH1: US Treasury Bond | AI1: Canadian Treasury Bond | AJ1: S&P 500 Composite | AK1: Portfolio Daily Return | AL1: MSCI World Return | AM1: Vanguard Total Market Return | AN1: S&P TSX60 Return | AO1: Vanguard FTSE Canada Return | AP1: Cumulative Portfolio | AQ1: Cumulative S&P 500 Composite | AR1: MSCI World | AS1: Vanguard Total Market | AT1: S&P TSX60 | AU1: Vanguard FTSE Canada
A2: 43832 | B2: 0.002324 | C2: -0.0057 | D2: 0.000604 | E2: -0.006219 | F2: -0.006504 | G2: 0.000686 | H2: -0.01193 | I2: -0.001509 | J2: -0.003854 | K2: 0.007304 | L2: 0.006313 | M2: 0.013307 | N2: 0.006583 | O2: 0.007356 | P2: -0.005293 | Q2: -0.001515 | R2: 0.006098 | S2: -0.001345 | T2: -0.020611 | U2: 0.010354 | V2: -0.0085365745 | W2: -0.00703909 | X2: 0 | Y2: -0.0064613209 | Z2: -0.002028835 | AA2: 0.0023464888 | AB2: -0.0014997698 | AC2: 0 | AD2: 0 | AE2: 0.0035548605 | AF2: -0.0029662829 | AG2: -0.0079560122 | AH2: -0.049946856 | AI2: 0.0050745339 | AJ2: 0.008379 | AK2: =Weights!E58 -> -0.0028856608 | AL2: 0.0045763649 | AM2: 0.0026346351 | AN2: 0.0027270115 | AO2: 0.0031673907 | AP2: =1*(1+AK2) -> 0.99711434 | AQ2: =1 * (1+AJ2) -> 1.008379 | AR2: =1 * (1+AL2) -> 1.0045764 | AS2: =1*(1+AM2) -> 1.0026346 | AT2: =1*(1+AN2) -> 1.002727 | AU2: =1*(1+AO2) -> 1.0031674
A3: 43833 | B3: -0.002834 | C3: -0.010647 | D3: -0.003219 | E3: -0.001399 | F3: -0.005456 | G3: -0.011578 | H3: -0.006726 | I3: -0.001763 | J3: 0.004594 | K3: -0.000884 | L3: -0.003513 | M3: -0.008755 | N3: -0.006976 | O3: -0.005253 | P3: -0.009024 | Q3: -0.007587 | R3: -0.030303 | S3: -0.005722 | T3: -0.013244 | U3: -0.001417 | V3: -0.014145096 | W3: -0.018979862 | X3: 0.001552683 | Y3: -0.0042230043 | Z3: 0.004006196 | AA3: 0.0045020468 | AB3: 0.0015020225 | AC3: -0.0058564323 | AD3: -0.0061038246 | AE3: -0.0013286575 | AF3: -0.0049586747 | AG3: 0.003941728 | AH3: 0.012863536 | AI3: -0.00091812742 | AJ3: -0.00706 | AK3: =Weights!E59 -> -0.0032232085 | AL3: 0.0075927521 | AM3: 0.0083120845 | AN3: -0.0011654043 | AO3: -0.00057431681 | AP3: =AP2*(1+AK3) -> 0.99390043 | AQ3: =AQ2 * (1 + AJ3) -> 1.0012598 | AR3: =AR2 * (1 +AL3) -> 1.0122039 | AS3: =AS2*(1+AM3) -> 1.0109686 | AT3: =AT2*(1+AN3) -> 1.0015584 | AU3: =AU2*(1+AO3) -> 1.0025913
A4: 43836 | B4: 0.002325 | C4: -0.002152 | D4: 0.001817 | E4: 0.003834 | F4: -0.000366 | G4: -0.001248 | H4: 0.001387 | I4: 0.009334 | J4: 0.002166 | K4: 0.001947 | L4: 0.00214 | M4: 0.005397 | N4: 0.007245 | O4: 0.004765 | P4: 0.01004 | Q4: 0.003058 | R4: 0.003906 | S4: -0.008802 | T4: -0.008457 | U4: 0.013755 | V4: 0.0037430096 | W4: 0.0069930399 | X4: 0.0062016325 | Y4: 0.00016969378 | Z4: 0.0095878107 | AA4: 0.0026892294 | AB4: 0.0080983209 | AC4: -0.014727518 | AD4: -0.0040939812 | AE4: -0.020572508 | AF4: 0.000664538 | AG4: -0.0037908512 | AH4: 0.0088349158 | AI4: 0 | AJ4: 0.003533 | AK4: =Weights!E60 -> 0.0018775086 | AL4: -0.0084397078 | AM4: -0.0063645592 | AN4: -0.0035006399 | AO4: -0.0029213684 | AP4: =AP3*(1+AK4) -> 0.99576649 | AQ4: =AQ3 * (1 + AJ4) -> 1.0047973 | AR4: =AR3 * (1 +AL4) -> 1.0036612 | AS4: =AS3*(1+AM4) -> 1.0045342 | AT4: =AT3*(1+AN4) -> 0.99805233 | AU4: =AU3*(1+AO4) -> 0.99966232
A5: 43837 | B5: 0.001031 | C5: -0.011117 | D5: 0.004231 | E5: -0.015718 | F5: -0.007682 | G5: 0.006107 | H5: -0.006191 | I5: -0.006748 | J5: -0.000961 | K5: -0.004594 | L5: -0.002764 | M5: 0.007321 | N5: 0.016347 | O5: -0.00564 | P5: -0.000693 | Q5: -0.003049 | R5: 0.015564 | S5: 0.002732 | T5: -0.002225 | U5: -0.003015 | V5: 0.00062158465 | W5: -0.0032407559 | X5: -0.0092449563 | Y5: 0.01348386 | Z5: -0.00094353779 | AA5: 0.0033970061 | AB5: 0.0098186505 | AC5: -0.0418536 | AD5: 0.0020555598 | AE5: -0.0040742419 | AF5: -0.0039840935 | AG5: -0.012503461 | AH5: 0.025725195 | AI5: -0.0027560724 | AJ5: -0.002803 | AK5: =Weights!E61 -> -0.00050052147 | AL5: 0.0056741102 | AM5: 0.0034159254 | AN5: -0.0023421618 | AO5: -0.0020307928 | AP5: =AP4*(1+AK5) -> 0.99526809 | AQ5: =AQ4 * (1 + AJ5) -> 1.0019808 | AR5: =AR4 * (1 +AL5) -> 1.009356 | AS5: =AS4*(1+AM5) -> 1.0079657 | AT5: =AT4*(1+AN5) -> 0.99571473 | AU5: =AU4*(1+AO5) -> 0.99763221
A6: 43838 | B6: -0.001545 | C6: 0.001846 | D6: 0.002006 | E6: 0.005149 | F6: 0.001843 | G6: -0.000138 | H6: 0.004263 | I6: 0.004278 | J6: 0.002404 | K6: 0.005857 | L6: 0.006048 | M6: 0.010174 | N6: 0.02166 | O6: 0.007219 | P6: -0.026602 | Q6: -0.050459 | R6: 0.009962 | S6: -0.04564 | T6: -0.002416 | U6: 0.007453 | V6: 0.0086955636 | W6: -0.0041802332 | X6: 0.023328058 | Y6: 0.0065267119 | Z6: -0.0048417369 | AA6: 0.0042765739 | AB6: -0.004124778 | AC6: 0.054602223 | AD6: 0.018461595 | AE6: -0.00018188282 | AF6: -0.02533336 | AG6: 0.002752797 | AH6: -0.0085378408 | AI6: 0.0013813703 | AJ6: 0.004902 | AK6: =Weights!E62 -> 0.0020024378 | AL6: -0.0026195775 | AM6: -0.0023705427 | AN6: 0.0027385729 | AO6: 0.0023254901 | AP6: =AP5*(1+AK6) -> 0.99726105 | AQ6: =AQ5 * (1 + AJ6) -> 1.0068926 | AR6: =AR5 * (1 +AL6) -> 1.006712 | AS6: =AS5*(1+AM6) -> 1.0055762 | AT6: =AT5*(1+AN6) -> 0.99844157 | AU6: =AU5*(1+AO6) -> 0.99995219
A7: 43839 | B7: -0.009283 | C7: -0.014403 | D7: -0.004405 | E7: 0.000668 | F7: 0.018215 | G7: 0.002966 | H7: 0.010938 | I7: -0.001754 | J7: -0.001439 | K7: -0.002108 | L7: -0.000125 | M7: 0.008153 | N7: 0.008816 | O7: 0.008383 | P7: -0.009981 | Q7: -0.017713 | R7: -0.016692 | S7: -0.008922 | T7: -0.003353 | U7: 0.005146 | V7: -0.0055418375 | W7: 0.0097947075 | X7: 0 | Y7: -0.0022446478 | Z7: 0.00059333134 | AA7: 0.0046133078 | AB7: 0.0047334721 | AC7: 0 | AD7: 0 | AE7: 0.0056376477 | AF7: 0.0054718303 | AG7: -0.010294048 | AH7: -0.017761029 | AI7: 0.0032198389 | AJ7: 0.006655 | AK7: =Weights!E63 -> -0.00098190585 | AL7: 0.002828583 | AM7: 0.0049357921 | AN7: -0.0027310936 | AO7: -0.002029881 | AP7: =AP6*(1+AK7) -> 0.99628183 | AQ7: =AQ6 * (1 + AJ7) -> 1.0135934 | AR7: =AR6 * (1 +AL7) -> 1.0095595 | AS7: =AS6*(1+AM7) -> 1.0105396 | AT7: =AT6*(1+AN7) -> 0.99571473 | AU7: =AU6*(1+AO7) -> 0.99792241
A8: 43840 | B8: 0.002082 | C8: 0.002379 | D8: -0.004626 | E8: -0.001929 | F8: 0.003433 | G8: -0.00227 | H8: 0.000969 | I8: 0.00251 | J8: 0.007445 | K8: -0.001965 | L8: 0.000125 | M8: 0.005709 | N8: -0.002497 | O8: -0.004379 | P8: 0.014642 | Q8: 0.011475 | R8: -0.00463 | S8: 0 | T8: -0.013645 | U8: 0.000747 | V8: 0.019195112 | W8: 0.0094687538 | X8: 0.0030442322 | Y8: 0.015664043 | Z8: 0.016127959 | AA8: 0.003708835 | AB8: -0.0047111719 | AC8: 0.020527827 | AD8: -0.0030213588 | AE8: 0.036346998 | AF8: 0.026530815 | AG8: 0.0090143144 | AH8: 0.01260274 | AI8: -0.0013753521 | AJ8: -0.002855 | AK8: =Weights!E64 -> 0.0060300591 | AL8: 0.0057419452 | AM8: 0.0062459356 | AN8: 0.0039125342 | AO8: 0.0024702806 | AP8: =AP7*(1+AK8) -> 1.0022895 | AQ8: =AQ7 * (1 + AJ8) -> 1.0106996 | AR8: =AR7 * (1 +AL8) -> 1.0153564 | AS8: =AS7*(1+AM8) -> 1.0168513 | AT8: =AT7*(1+AN8) -> 0.9996105 | AU8: =AU7*(1+AO8) -> 1.0003876
A9: 43843 | B9: 0.002078 | C9: 0.002712 | D9: 0.004849 | E9: 0.014867 | F9: 0.010805 | G9: 0.004412 | H9: 0.00734 | I9: 0.008262 | J9: 0.004052 | K9: 0.002684 | L9: 0.004759 | M9: -0.002838 | N9: -0.000209 | O9: 0.008796 | P9: 0.004258 | Q9: -0.037277 | R9: 0.048837 | S9: -0.011163 | T9: 0.01137 | U9: 0.013217 | V9: 0.0030376149 | W9: -0.0059483244 | X9: 0.0075872236 | Y9: 0.0086136803 | Z9: -0.001808527 | AA9: -0.0042231448 | AB9: -0.0026628749 | AC9: 0.0057471176 | AD9: -0.0010098884 | AE9: 0.012737525 | AF9: -0.0069583428 | AG9: 0.014706024 | AH9: -0.016233815 | AI9: 0.0013772463 | AJ9: 0.006976 | AK9: =Weights!E65 -> 0.0029801858 | AL9: -0.0040064305 | AM9: -0.002892655 | AN9: 0.0019486865 | AO9: 0.0042032327 | AP9: =AP8*(1+AK9) -> 1.0052765 | AQ9: =AQ8 * (1 + AJ9) -> 1.0177503 | AR9: =AR8 * (1 +AL9) -> 1.0112884 | AS9: =AS8*(1+AM9) -> 1.0139099 | AT9: =AT8*(1+AN9) -> 1.0015584 | AU9: =AU8*(1+AO9) -> 1.0045924
A10: 43844 | B10: -0.002592 | C10: -0.00186 | D10: 0.000402 | E10: 0.002344 | F10: -0.002316 | G10: 0.005628 | H10: -0.001521 | I10: -0.000993 | J10: -0.002374 | K10: -0.00464 | L10: 0.002867 | M10: -0.001897 | N10: -0.001878 | O10: 0.000316 | P10: 0.008952 | Q10: 0.021886 | R10: -0.023651 | S10: 0.009833 | T10: 0.011804 | U10: 0.000736 | V10: 0.0054511335 | W10: -0.0050633158 | X10: -0.0060240729 | Y10: 0.00056925891 | Z10: -0.00064325009 | AA10: 0.004770866 | AB10: -0.001186602 | AC10: -0.0071428099 | AD10: -0.0091001285 | AE10: 0.0097346375 | AF10: -0.020353555 | AG10: 0.019503772 | AH10: -0.016501635 | AI10: 0.0027514388 | AJ10: -0.001515 | AK10: =Weights!E66 -> 0.000114096 | AL10: 0.0064359913 | AM10: 0.006829687 | AN10: 0.001944462 | AO10: -0.00028861601 | AP10: =AP9*(1+AK10) -> 1.0053912 | AQ10: =AQ9 * (1 + AJ10) -> 1.0162084 | AR10: =AR9 * (1 +AL10) -> 1.017797 | AS10: =AS9*(1+AM10) -> 1.0208346 | AT10: =AT9*(1+AN10) -> 1.0035059 | AU10: =AU9*(1+AO10) -> 1.0043025
A11: 43845 | B11: 0.004418 | C11: 0.001016 | D11: -0.002814 | E11: 0.017172 | F11: 0.0125 | G11: 0.003344 | H11: 0.010185 | I11: -0.000746 | J11: 0.007139 | K11: 0.00771 | L11: 0.003107 | M11: -0.013308 | N11: 0.00209 | O11: 0.002526 | P11: 0.01611 | Q11: 0.018122 | R11: -0.017411 | S11: 0.015146 | T11: -0.010556 | U11: 0.011458 | V11: 0.0018073161 | W11: 0.006477129 | X11: 0.0045453333 | Y11: 0.013656361 | Z11: -0.0047675985 | AA11: 0.0047489187 | AB11: 0.0071277722 | AC11: -0.0071942699 | AD11: 0.0051020086 | AE11: -0.0080195531 | AF11: -0.0095369386 | AG11: 0.01036275 | AH11: 0.011744982 | AI11: -0.00045733231 | AJ11: 0.00187 | AK11: =Weights!E67 -> 0.0034826712 | AL11: -0.0019983288 | AM11: -0.00054051063 | AN11: 0.0042704686 | AO11: 0.0046200256 | AP11: =AP10*(1+AK11) -> 1.0088926 | AQ11: =AQ10 * (1 + AJ11) -> 1.0181087 | AR11: =AR10 * (1 +AL11) -> 1.0157632 | AS11: =AS10*(1+AM11) -> 1.0202828 | AT11: =AT10*(1+AN11) -> 1.0077914 | AU11: =AU10*(1+AO11) -> 1.0089424
A12: 43846 | B12: 0.008538 | C12: 0.009645 | D12: 0.00262 | E12: 0.002945 | F12: 0.002116 | G12: 0.008095 | H12: 0.000873 | I12: 0.007214 | J12: 0.00827 | K12: 0.008897 | L12: 0.008921 | M12: 0.00578 | N12: 0.008344 | O12: 0.012664 | P12: 0.006893 | Q12: -0.016181 | R12: -0.010015 | S12: -0.004263 | T12: -0.001497 | U12: 0.015174 | V12: 0.0048106187 | W12: 0.032176212 | X12: 0 | Y12: 0.0073776787 | Z12: 0.0082580827 | AA12: 0.017854004 | AB12: 0.004718489 | AC12: 0 | AD12: 0 | AE12: 0.0064504116 | AF12: -0.0020632893 | AG12: -0.00039432713 | AH12: 0.014925346 | AI12: 0.00045754156 | AJ12: 0.008367 | AK12: =Weights!E68 -> 0.0056659309 | AL12: 0.001401772 | AM12: 0.0024624891 | AN12: -0.0007729744 | AO12: 0 | AP12: =AP11*(1+AK12) -> 1.0146089 | AQ12: =AQ11 * (1 + AJ12) -> 1.0266272 | AR12: =AR11 * (1 +AL12) -> 1.017187 | AS12: =AS11*(1+AM12) -> 1.0227953 | AT12: =AT11*(1+AN12) -> 1.0070124 | AU12: =AU11*(1+AO12) -> 1.0089424
A13: 43847 | B13: 0.00744 | C13: 0.007709 | D13: -0.000804 | E13: 0.011819 | F13: 0.002112 | G13: 0.006545 | H13: 0.002697 | I13: 0.000741 | J13: 0.013593 | K13: 0.000705 | L13: 0.001105 | M13: 0.011973 | N13: 0.005999 | O13: -0.000995 | P13: -0.007759 | Q13: 0.008224 | R13: 0.001556 | S13: 0.006778 | T13: 0.008622 | U13: 0.005016 | V13: 0.014362616 | W13: -0.0022263584 | X13: 0.0030211362 | Y13: 0.0062091938 | Z13: -0.0023318418 | AA13: 0.0079105399 | AB13: 0.0076314524 | AC13: -0.0029281789 | AD13: 0.0010159848 | AE13: -0.0045290194 | AF13: -0.00068910092 | AG13: 0 | AH13: 0 | AI13: 0.00045722766 | AJ13: 0.003862 | AK13: =Weights!E69 -> 0.003682072 | AL13: 0.00799844 | AM13: 0.0085675477 | AN13: 0.0050287389 | AO13: 0.0034497406 | AP13: =AP12*(1+AK13) -> 1.0183448 | AQ13: =AQ12 * (1 + AJ13) -> 1.030592 | AR13: =AR12 * (1 +AL13) -> 1.0253229 | AS13: =AS12*(1+AM13) -> 1.0315581 | AT13: =AT12*(1+AN13) -> 1.0120764 | AU13: =AU12*(1+AO13) -> 1.012423
A14: 43851 | B14: 0.005093 | C14: 0.00316 | D14: -0.006237 | E14: 0.004248 | F14: 0.004039 | G14: 0.00067 | H14: -0.002532 | I14: 0.005429 | J14: 0.012486 | K14: -0.003701 | L14: 0.00184 | M14: -0.024136 | N14: -0.006786 | O14: 0.008532 | P14: 0.00529 | Q14: 0.03752 | R14: -0.04662 | S14: 0.022679 | T14: -0.026947 | U14: -0.001528 | V14: 0.006489579 | W14: -0.018076627 | X14: -0.0045181574 | Y14: -0.010205677 | Z14: -0.012007529 | AA14: 0.012625722 | AB14: 0.0072823797 | AC14: -0.0014683143 | AD14: -0.0030457149 | AE14: 0.013477308 | AF14: -0.025172392 | AG14: -0.01881071 | AH14: -0.036492328 | AI14: 0.0031989216 | AJ14: -0.002652 | AK14: =Weights!E70 -> -0.0033354435 | AL14: 0.0033721992 | AM14: 0.002494853 | AN14: 0.0023095352 | AO14: 0.0028643477 | AP14: =AP13*(1+AK14) -> 1.0149482 | AQ14: =AQ13 * (1 + AJ14) -> 1.0278589 | AR14: =AR13 * (1 +AL14) -> 1.0287805 | AS14: =AS13*(1+AM14) -> 1.0341317 | AT14: =AT13*(1+AN14) -> 1.0144138 | AU14: =AU13*(1+AO14) -> 1.0153229
... A1259: 45657 | B1259: 0.008178 | C1259: 0.009849 | D1259: 0.008864 | E1259: 0.002241 | F1259: 0.003708 | G1259: 0.00893 | H1259: 0.003351 | I1259: 0.00736 | J1259: -0.002878 | K1259: 0.003014 | L1259: -0.000249 | M1259: 0.002612 | N1259: 0.000675 | O1259: -0.003529 | P1259: 0.005946 | Q1259: 0.00304 | R1259: -0.002096 | S1259: 0.002853 | T1259: 0.012084 | U1259: 0.002395 | V1259: 0.014634146 | W1259: 0.0081201777 | X1259: 0.013793068 | Y1259: -0.0060841024 | Z1259: 0.0041586296 | AA1259: -0.026681668 | AB1259: 0.0033819977 | AC1259: 0.0086741587 | AD1259: -0.007058734 | AE1259: 0.012237319 | AF1259: -0.0028222013 | AG1259: -0.019351452 | AH1259: -0.00093494862 | AI1259: 0.00050123227 | AJ1259: -0.004285 | AK1259: =Weights!E1315 -> 0.0014178737 | AL1259: -0.0093909323 | AM1259: -0.011051799 | AN1259: -0.0071865988 | AO1259: -0.007481474 | AP1259: =AP1258*(1+AK1259) -> 1.7972278 | AQ1259: =AQ1258 * (1 + AJ1259) -> 1.8204587 | AR1259: =AR1258 * (1 +AL1259) -> 1.7227317 | AS1259: =AS1258*(1+AM1259) -> 1.9228402 | AT1259: =AT1258*(1+AN1259) -> 1.6899321 | AU1259: =AU1258*(1+AO1259) -> 1.6907818

Sheet Final_Analysis
A1: Date | B1: Cumulative Portfolio | C1: Cumulative Portfolio Year-end | D1: S&P 500 Composite | E1: S&P 500 Composite Year End | F1: MSCI World | G1: MSCI Year End | H1: Vanguard Total Market | I1: Vanguard Year End | J1: S&P TSX60 | K1: TSX60 Year End | L1: Vanguard FTSE Canada | M1: FTSE Year End
A2: 43832 | B2: =1*(1+'Daily Returns'!AK2) -> 0.99711434 | C2: =1*(1+'Daily Returns'!AK2) -> 0.99711434 | D2: =1 * (1+'Daily Returns'!AJ2) -> 1.008379 | E2: =1 * (1+'Daily Returns'!AJ2) -> 1.008379 | F2: =1 * (1+'Daily Returns'!AL2) -> 1.0045764 | G2: =1 * (1+'Daily Returns'!AL2) -> 1.0045764 | H2: =1*(1+'Daily Returns'!AM2) -> 1.0026346 | I2: =1*(1+'Daily Returns'!AM2) -> 1.0026346 | J2: =1*(1+'Daily Returns'!AN2) -> 1.002727 | K2: =1*(1+'Daily Returns'!AN2) -> 1.002727 | L2: =1*(1+'Daily Returns'!AO2) -> 1.0031674 | M2: =1*(1+'Daily Returns'!AO2) -> 1.0031674
A3: 43833 | B3: ='Daily Returns'!AP2*(1+'Daily Returns'!AK3) -> 0.99390043 | D3: ='Daily Returns'!AQ2 * (1 + 'Daily Returns'!AJ3) -> 1.0012598 | F3: ='Daily Returns'!AR2 * (1 +'Daily Returns'!AL3) -> 1.0122039 | H3: ='Daily Returns'!AS2*(1+'Daily Returns'!AM3) -> 1.0109686 | J3: ='Daily Returns'!AT2*(1+'Daily Returns'!AN3) -> 1.0015584 | L3: ='Daily Returns'!AU2*(1+'Daily Returns'!AO3) -> 1.0025913
A4: 43836 | B4: ='Daily Returns'!AP3*(1+'Daily Returns'!AK4) -> 0.99576649 | D4: ='Daily Returns'!AQ3 * (1 + 'Daily Returns'!AJ4) -> 1.0047973 | F4: ='Daily Returns'!AR3 * (1 +'Daily Returns'!AL4) -> 1.0036612 | H4: ='Daily Returns'!AS3*(1+'Daily Returns'!AM4) -> 1.0045342 | J4: ='Daily Returns'!AT3*(1+'Daily Returns'!AN4) -> 0.99805233 | L4: ='Daily Returns'!AU3*(1+'Daily Returns'!AO4) -> 0.99966232
A5: 43837 | B5: ='Daily Returns'!AP4*(1+'Daily Returns'!AK5) -> 0.99526809 | D5: ='Daily Returns'!AQ4 * (1 + 'Daily Returns'!AJ5) -> 1.0019808 | F5: ='Daily Returns'!AR4 * (1 +'Daily Returns'!AL5) -> 1.009356 | H5: ='Daily Returns'!AS4*(1+'Daily Returns'!AM5) -> 1.0079657 | J5: ='Daily Returns'!AT4*(1+'Daily Returns'!AN5) -> 0.99571473 | L5: ='Daily Returns'!AU4*(1+'Daily Returns'!AO5) -> 0.99763221
A6: 43838 | B6: ='Daily Returns'!AP5*(1+'Daily Returns'!AK6) -> 0.99726105 | D6: ='Daily Returns'!AQ5 * (1 + 'Daily Returns'!AJ6) -> 1.0068926 | F6: ='Daily Returns'!AR5 * (1 +'Daily Returns'!AL6) -> 1.006712 | H6: ='Daily Returns'!AS5*(1+'Daily Returns'!AM6) -> 1.0055762 | J6: ='Daily Returns'!AT5*(1+'Daily Returns'!AN6) -> 0.99844157 | L6: ='Daily Returns'!AU5*(1+'Daily Returns'!AO6) -> 0.99995219
A7: 43839 | B7: ='Daily Returns'!AP6*(1+'Daily Returns'!AK7) -> 0.99628183 | D7: ='Daily Returns'!AQ6 * (1 + 'Daily Returns'!AJ7) -> 1.0135934 | F7: ='Daily Returns'!AR6 * (1 +'Daily Returns'!AL7) -> 1.0095595 | H7: ='Daily Returns'!AS6*(1+'Daily Returns'!AM7) -> 1.0105396 | J7: ='Daily Returns'!AT6*(1+'Daily Returns'!AN7) -> 0.99571473 | L7: ='Daily Returns'!AU6*(1+'Daily Returns'!AO7) -> 0.99792241
A8: 43840 | B8: ='Daily Returns'!AP7*(1+'Daily Returns'!AK8) -> 1.0022895 | D8: ='Daily Returns'!AQ7 * (1 + 'Daily Returns'!AJ8) -> 1.0106996 | F8: ='Daily Returns'!AR7 * (1 +'Daily Returns'!AL8) -> 1.0153564 | H8: ='Daily Returns'!AS7*(1+'Daily Returns'!AM8) -> 1.0168513 | J8: ='Daily Returns'!AT7*(1+'Daily Returns'!AN8) -> 0.9996105 | L8: ='Daily Returns'!AU7*(1+'Daily Returns'!AO8) -> 1.0003876
A9: 43843 | B9: ='Daily Returns'!AP8*(1+'Daily Returns'!AK9) -> 1.0052765 | D9: ='Daily Returns'!AQ8 * (1 + 'Daily Returns'!AJ9) -> 1.0177503 | F9: ='Daily Returns'!AR8 * (1 +'Daily Returns'!AL9) -> 1.0112884 | H9: ='Daily Returns'!AS8*(1+'Daily Returns'!AM9) -> 1.0139099 | J9: ='Daily Returns'!AT8*(1+'Daily Returns'!AN9) -> 1.0015584 | L9: ='Daily Returns'!AU8*(1+'Daily Returns'!AO9) -> 1.0045924
A10: 43844 | B10: ='Daily Returns'!AP9*(1+'Daily Returns'!AK10) -> 1.0053912 | D10: ='Daily Returns'!AQ9 * (1 + 'Daily Returns'!AJ10) -> 1.0162084 | F10: ='Daily Returns'!AR9 * (1 +'Daily Returns'!AL10) -> 1.017797 | H10: ='Daily Returns'!AS9*(1+'Daily Returns'!AM10) -> 1.0208346 | J10: ='Daily Returns'!AT9*(1+'Daily Returns'!AN10) -> 1.0035059 | L10: ='Daily Returns'!AU9*(1+'Daily Returns'!AO10) -> 1.0043025
A11: 43845 | B11: ='Daily Returns'!AP10*(1+'Daily Returns'!AK11) -> 1.0088926 | D11: ='Daily Returns'!AQ10 * (1 + 'Daily Returns'!AJ11) -> 1.0181087 | F11: ='Daily Returns'!AR10 * (1 +'Daily Returns'!AL11) -> 1.0157632 | H11: ='Daily Returns'!AS10*(1+'Daily Returns'!AM11) -> 1.0202828 | J11: ='Daily Returns'!AT10*(1+'Daily Returns'!AN11) -> 1.0077914 | L11: ='Daily Returns'!AU10*(1+'Daily Returns'!AO11) -> 1.0089424
A12: 43846 | B12: ='Daily Returns'!AP11*(1+'Daily Returns'!AK12) -> 1.0146089 | D12: ='Daily Returns'!AQ11 * (1 + 'Daily Returns'!AJ12) -> 1.0266272 | F12: ='Daily Returns'!AR11 * (1 +'Daily Returns'!AL12) -> 1.017187 | H12: ='Daily Returns'!AS11*(1+'Daily Returns'!AM12) -> 1.0227953 | J12: ='Daily Returns'!AT11*(1+'Daily Returns'!AN12) -> 1.0070124 | L12: ='Daily Returns'!AU11*(1+'Daily Returns'!AO12) -> 1.0089424
A13: 43847 | B13: ='Daily Returns'!AP12*(1+'Daily Returns'!AK13) -> 1.0183448 | D13: ='Daily Returns'!AQ12 * (1 + 'Daily Returns'!AJ13) -> 1.030592 | F13: ='Daily Returns'!AR12 * (1 +'Daily Returns'!AL13) -> 1.0253229 | H13: ='Daily Returns'!AS12*(1+'Daily Returns'!AM13) -> 1.0315581 | J13: ='Daily Returns'!AT12*(1+'Daily Returns'!AN13) -> 1.0120764 | L13: ='Daily Returns'!AU12*(1+'Daily Returns'!AO13) -> 1.012423
A14: 43851 | B14: ='Daily Returns'!AP13*(1+'Daily Returns'!AK14) -> 1.0149482 | D14: ='Daily Returns'!AQ13 * (1 + 'Daily Returns'!AJ14) -> 1.0278589 | F14: ='Daily Returns'!AR13 * (1 +'Daily Returns'!AL14) -> 1.0287805 | H14: ='Daily Returns'!AS13*(1+'Daily Returns'!AM14) -> 1.0341317 | J14: ='Daily Returns'!AT13*(1+'Daily Returns'!AN14) -> 1.0144138 | L14: ='Daily Returns'!AU13*(1+'Daily Returns'!AO14) -> 1.0153229
... A253: 44195 | B253: ='Daily Returns'!AP252*(1+'Daily Returns'!AK253) -> 1.175943 | D253: ='Daily Returns'!AQ252 * (1 + 'Daily Returns'!AJ253) -> 1.1551506 | F253: ='Daily Returns'!AR252 * (1 +'Daily Returns'!AL253) -> 1.1603521 | H253: ='Daily Returns'!AS252*(1+'Daily Returns'!AM253) -> 1.2051575 | J253: ='Daily Returns'!AT252*(1+'Daily Returns'!AN253) -> 1.0606603 | L253: ='Daily Returns'!AU252*(1+'Daily Returns'!AO253) -> 1.0551435
A254: 44196 | B254: ='Daily Returns'!AP253*(1+'Daily Returns'!AK254) -> 1.1740236 | C254: ='Daily Returns'!AP253*(1+'Daily Returns'!AK254) -> 1.1740236 | D254: ='Daily Returns'!AQ253 * (1 + 'Daily Returns'!AJ254) -> 1.1625886 | E254: ='Daily Returns'!AQ253 * (1 + 'Daily Returns'!AJ254) -> 1.1625886 | F254: ='Daily Returns'!AR253 * (1 +'Daily Returns'!AL254) -> 1.1619042 | G254: ='Daily Returns'!AR253 * (1 +'Daily Returns'!AL254) -> 1.1619042 | H254: ='Daily Returns'!AS253*(1+'Daily Returns'!AM254) -> 1.2084005 | I254: ='Daily Returns'!AS253*(1+'Daily Returns'!AM254) -> 1.2084005 | J254: ='Daily Returns'!AT253*(1+'Daily Returns'!AN254) -> 1.0630729 | K254: ='Daily Returns'!AT253*(1+'Daily Returns'!AN254) -> 1.0630729 | L254: ='Daily Returns'!AU253*(1+'Daily Returns'!AO254) -> 1.0569248 | M254: ='Daily Returns'!AU253*(1+'Daily Returns'!AO254) -> 1.0569248
A255: 44200 | B255: ='Daily Returns'!AP254*(1+'Daily Returns'!AK255) -> 1.1824839 | D255: ='Daily Returns'!AQ254 * (1 + 'Daily Returns'!AJ255) -> 1.1454346 | F255: ='Daily Returns'!AR254 * (1 +'Daily Returns'!AL255) -> 1.1631459 | H255: ='Daily Returns'!AS254*(1+'Daily Returns'!AM255) -> 1.2139513 | J255: ='Daily Returns'!AT254*(1+'Daily Returns'!AN255) -> 1.058248 | L255: ='Daily Returns'!AU254*(1+'Daily Returns'!AO255) -> 1.0527683
A256: 44201 | B256: ='Daily Returns'!AP255*(1+'Daily Returns'!AK256) -> 1.1885332 | D256: ='Daily Returns'!AQ255 * (1 + 'Daily Returns'!AJ256) -> 1.1535477 | F256: ='Daily Returns'!AR255 * (1 +'Daily Returns'!AL256) -> 1.1550749 | H256: ='Daily Returns'!AS255*(1+'Daily Returns'!AM256) -> 1.196675 | J256: ='Daily Returns'!AT255*(1+'Daily Returns'!AN256) -> 1.0566398 | L256: ='Daily Returns'!AU255*(1+'Daily Returns'!AO256) -> 1.0532467
A257: 44202 | B257: ='Daily Returns'!AP256*(1+'Daily Returns'!AK257) -> 1.1995519 | D257: ='Daily Returns'!AQ256 * (1 + 'Daily Returns'!AJ257) -> 1.1601344 | F257: ='Daily Returns'!AR256 * (1 +'Daily Returns'!AL257) -> 1.1639734 | H257: ='Daily Returns'!AS256*(1+'Daily Returns'!AM257) -> 1.2063425 | J257: ='Daily Returns'!AT256*(1+'Daily Returns'!AN257) -> 1.0481963 | L257: ='Daily Returns'!AU256*(1+'Daily Returns'!AO257) -> 1.0457748
A258: 44203 | B258: ='Daily Returns'!AP257*(1+'Daily Returns'!AK258) -> 1.2021547 | D258: ='Daily Returns'!AQ257 * (1 + 'Daily Returns'!AJ258) -> 1.177359 | F258: ='Daily Returns'!AR257 * (1 +'Daily Returns'!AL258) -> 1.1710098 | H258: ='Daily Returns'!AS257*(1+'Daily Returns'!AM258) -> 1.2171947 | J258: ='Daily Returns'!AT257*(1+'Daily Returns'!AN258) -> 1.0542273 | L258: ='Daily Returns'!AU257*(1+'Daily Returns'!AO258) -> 1.0508555
A259: 44204 | B259: ='Daily Returns'!AP258*(1+'Daily Returns'!AK259) -> 1.202281 | D259: ='Daily Returns'!AQ258 * (1 + 'Daily Returns'!AJ259) -> 1.183825 | F259: ='Daily Returns'!AR258 * (1 +'Daily Returns'!AL259) -> 1.1844615 | H259: ='Daily Returns'!AS258*(1+'Daily Returns'!AM259) -> 1.2367161 | J259: ='Daily Returns'!AT258*(1+'Daily Returns'!AN259) -> 1.0642791 | L259: ='Daily Returns'!AU258*(1+'Daily Returns'!AO259) -> 1.0616153
A260: 44207 | B260: ='Daily Returns'!AP259*(1+'Daily Returns'!AK260) -> 1.1952933 | D260: ='Daily Returns'!AQ259 * (1 + 'Daily Returns'!AJ260) -> 1.176065 | F260: ='Daily Returns'!AR259 * (1 +'Daily Returns'!AL260) -> 1.1931533 | H260: ='Daily Returns'!AS259*(1+'Daily Returns'!AM260) -> 1.2427035 | J260: ='Daily Returns'!AT259*(1+'Daily Returns'!AN260) -> 1.0747329 | L260: ='Daily Returns'!AU259*(1+'Daily Returns'!AO260) -> 1.0708805
A261: 44208 | B261: ='Daily Returns'!AP260*(1+'Daily Returns'!AK261) -> 1.1982376 | D261: ='Daily Returns'!AQ260 * (1 + 'Daily Returns'!AJ261) -> 1.1765543 | F261: ='Daily Returns'!AR260 * (1 +'Daily Returns'!AL261) -> 1.182185 | H261: ='Daily Returns'!AS260*(1+'Daily Returns'!AM261) -> 1.2352817 | J261: ='Daily Returns'!AT260*(1+'Daily Returns'!AN261) -> 1.0875992 | L261: ='Daily Returns'!AU260*(1+'Daily Returns'!AO261) -> 1.0834336
A262: 44209 | B262: ='Daily Returns'!AP261*(1+'Daily Returns'!AK262) -> 1.1976112 | D262: ='Daily Returns'!AQ261 * (1 + 'Daily Returns'!AJ262) -> 1.1792321 | F262: ='Daily Returns'!AR261 * (1 +'Daily Returns'!AL262) -> 1.1854962 | H262: ='Daily Returns'!AS261*(1+'Daily Returns'!AM262) -> 1.2396474 | J262: ='Daily Returns'!AT261*(1+'Daily Returns'!AN262) -> 1.0892075 | L262: ='Daily Returns'!AU261*(1+'Daily Returns'!AO262) -> 1.0837322
A263: 44210 | B263: ='Daily Returns'!AP262*(1+'Daily Returns'!AK263) -> 1.2047462 | D263: ='Daily Returns'!AQ262 * (1 + 'Daily Returns'!AJ263) -> 1.1748065 | F263: ='Daily Returns'!AR262 * (1 +'Daily Returns'!AL263) -> 1.1873587 | H263: ='Daily Returns'!AS262*(1+'Daily Returns'!AM263) -> 1.2410195 | J263: ='Daily Returns'!AT262*(1+'Daily Returns'!AN263) -> 1.0843826 | L263: ='Daily Returns'!AU262*(1+'Daily Returns'!AO263) -> 1.0780536
A264: 44211 | B264: ='Daily Returns'!AP263*(1+'Daily Returns'!AK264) -> 1.2001401 | D264: ='Daily Returns'!AQ263 * (1 + 'Daily Returns'!AJ264) -> 1.1663596 | F264: ='Daily Returns'!AR263 * (1 +'Daily Returns'!AL264) -> 1.1864273 | H264: ='Daily Returns'!AS263*(1+'Daily Returns'!AM264) -> 1.2398346 | J264: ='Daily Returns'!AT263*(1+'Daily Returns'!AN264) -> 1.086393 | L264: ='Daily Returns'!AU263*(1+'Daily Returns'!AO264) -> 1.081341
A265: 44215 | B265: ='Daily Returns'!AP264*(1+'Daily Returns'!AK265) -> 1.2144748 | D265: ='Daily Returns'!AQ264 * (1 + 'Daily Returns'!AJ265) -> 1.1758491 | F265: ='Daily Returns'!AR264 * (1 +'Daily Returns'!AL265) -> 1.1749418 | H265: ='Daily Returns'!AS264*(1+'Daily Returns'!AM265) -> 1.2290446 | J265: ='Daily Returns'!AT264*(1+'Daily Returns'!AN265) -> 1.0839805 | L265: ='Daily Returns'!AU264*(1+'Daily Returns'!AO265) -> 1.0786513
A266: 44216 | B266: ='Daily Returns'!AP265*(1+'Daily Returns'!AK266) -> 1.2246193 | D266: ='Daily Returns'!AQ265 * (1 + 'Daily Returns'!AJ266) -> 1.1922357 | F266: ='Daily Returns'!AR265 * (1 +'Daily Returns'!AL266) -> 1.1844615 | H266: ='Daily Returns'!AS265*(1+'Daily Returns'!AM266) -> 1.2402711 | J266: ='Daily Returns'!AT265*(1+'Daily Returns'!AN266) -> 1.0855886 | L266: ='Daily Returns'!AU265*(1+'Daily Returns'!AO266) -> 1.0795481
... A505: 44560 | B505: ='Daily Returns'!AP504*(1+'Daily Returns'!AK505) -> 1.484367 | D505: ='Daily Returns'!AQ504 * (1 + 'Daily Returns'!AJ505) -> 1.4791165 | F505: ='Daily Returns'!AR504 * (1 +'Daily Returns'!AL505) -> 1.4276039 | H505: ='Daily Returns'!AS504*(1+'Daily Returns'!AM505) -> 1.5330471 | J505: ='Daily Returns'!AT504*(1+'Daily Returns'!AN505) -> 1.343123 | L505: ='Daily Returns'!AU504*(1+'Daily Returns'!AO505) -> 1.3142554
A506: 44561 | B506: ='Daily Returns'!AP505*(1+'Daily Returns'!AK506) -> 1.4885118 | C506: ='Daily Returns'!AP505*(1+'Daily Returns'!AK506) -> 1.4885118 | D506: ='Daily Returns'!AQ505 * (1 + 'Daily Returns'!AJ506) -> 1.4752324 | E506: ='Daily Returns'!AQ505 * (1 + 'Daily Returns'!AJ506) -> 1.4752324 | F506: ='Daily Returns'!AR505 * (1 +'Daily Returns'!AL506) -> 1.4255755 | G506: ='Daily Returns'!AR505 * (1 +'Daily Returns'!AL506) -> 1.4255755 | H506: ='Daily Returns'!AS505*(1+'Daily Returns'!AM506) -> 1.5305827 | I506: ='Daily Returns'!AS505*(1+'Daily Returns'!AM506) -> 1.5305827 | J506: ='Daily Returns'!AT505*(1+'Daily Returns'!AN506) -> 1.3509652 | K506: ='Daily Returns'!AT505*(1+'Daily Returns'!AN506) -> 1.3509652 | L506: ='Daily Returns'!AU505*(1+'Daily Returns'!AO506) -> 1.3206634 | M506: ='Daily Returns'!AU505*(1+'Daily Returns'!AO506) -> 1.3206634
A507: 44564 | B507: ='Daily Returns'!AP506*(1+'Daily Returns'!AK507) -> 1.48683 | D507: ='Daily Returns'!AQ506 * (1 + 'Daily Returns'!AJ507) -> 1.4846355 | F507: ='Daily Returns'!AR506 * (1 +'Daily Returns'!AL507) -> 1.4222124 | H507: ='Daily Returns'!AS506*(1+'Daily Returns'!AM507) -> 1.5257167 | J507: ='Daily Returns'!AT506*(1+'Daily Returns'!AN507) -> 1.3476633 | L507: ='Daily Returns'!AU506*(1+'Daily Returns'!AO507) -> 1.3189448
A508: 44565 | B508: ='Daily Returns'!AP507*(1+'Daily Returns'!AK508) -> 1.4846034 | D508: ='Daily Returns'!AQ507 * (1 + 'Daily Returns'!AJ508) -> 1.4837002 | F508: ='Daily Returns'!AR507 * (1 +'Daily Returns'!AL508) -> 1.4298846 | H508: ='Daily Returns'!AS507*(1+'Daily Returns'!AM508) -> 1.5353853 | J508: ='Daily Returns'!AT507*(1+'Daily Returns'!AN508) -> 1.3422973 | L508: ='Daily Returns'!AU507*(1+'Daily Returns'!AO508) -> 1.3140351
A509: 44566 | B509: ='Daily Returns'!AP508*(1+'Daily Returns'!AK509) -> 1.4867145 | D509: ='Daily Returns'!AQ508 * (1 + 'Daily Returns'!AJ509) -> 1.4549268 | F509: ='Daily Returns'!AR508 * (1 +'Daily Returns'!AL509) -> 1.4298846 | H509: ='Daily Returns'!AS508*(1+'Daily Returns'!AM509) -> 1.5324784 | J509: ='Daily Returns'!AT508*(1+'Daily Returns'!AN509) -> 1.343123 | L509: ='Daily Returns'!AU508*(1+'Daily Returns'!AO509) -> 1.315569
A510: 44567 | B510: ='Daily Returns'!AP509*(1+'Daily Returns'!AK510) -> 1.4869803 | D510: ='Daily Returns'!AQ509 * (1 + 'Daily Returns'!AJ510) -> 1.4535242 | F510: ='Daily Returns'!AR509 * (1 +'Daily Returns'!AL510) -> 1.4059219 | H510: ='Daily Returns'!AS509*(1+'Daily Returns'!AM510) -> 1.4992392 | J510: ='Daily Returns'!AT509*(1+'Daily Returns'!AN510) -> 1.3328038 | L510: ='Daily Returns'!AU509*(1+'Daily Returns'!AO510) -> 1.3042151
A511: 44568 | B511: ='Daily Returns'!AP510*(1+'Daily Returns'!AK511) -> 1.4937322 | D511: ='Daily Returns'!AQ510 * (1 + 'Daily Returns'!AJ511) -> 1.4476375 | F511: ='Daily Returns'!AR510 * (1 +'Daily Returns'!AL511) -> 1.4032942 | H511: ='Daily Returns'!AS510*(1+'Daily Returns'!AM511) -> 1.4988599 | J511: ='Daily Returns'!AT510*(1+'Daily Returns'!AN511) -> 1.3356932 | L511: ='Daily Returns'!AU510*(1+'Daily Returns'!AO511) -> 1.3069767
A512: 44571 | B512: ='Daily Returns'!AP511*(1+'Daily Returns'!AK512) -> 1.489217 | D512: ='Daily Returns'!AQ511 * (1 + 'Daily Returns'!AJ512) -> 1.4455514 | F512: ='Daily Returns'!AR511 * (1 +'Daily Returns'!AL512) -> 1.3998261 | H512: ='Daily Returns'!AS511*(1+'Daily Returns'!AM512) -> 1.4920352 | J512: ='Daily Returns'!AT511*(1+'Daily Returns'!AN512) -> 1.3377568 | L512: ='Daily Returns'!AU511*(1+'Daily Returns'!AO512) -> 1.3085111
A513: 44572 | B513: ='Daily Returns'!AP512*(1+'Daily Returns'!AK513) -> 1.4922489 | D513: ='Daily Returns'!AQ512 * (1 + 'Daily Returns'!AJ513) -> 1.4587927 | F513: ='Daily Returns'!AR512 * (1 +'Daily Returns'!AL513) -> 1.3940454 | H513: ='Daily Returns'!AS512*(1+'Daily Returns'!AM513) -> 1.4894444 | J513: ='Daily Returns'!AT512*(1+'Daily Returns'!AN513) -> 1.3381694 | L513: ='Daily Returns'!AU512*(1+'Daily Returns'!AO513) -> 1.3072837
A514: 44573 | B514: ='Daily Returns'!AP513*(1+'Daily Returns'!AK514) -> 1.5076304 | D514: ='Daily Returns'!AQ513 * (1 + 'Daily Returns'!AJ514) -> 1.4629035 | F514: ='Daily Returns'!AR513 * (1 +'Daily Returns'!AL514) -> 1.4085492 | H514: ='Daily Returns'!AS513*(1+'Daily Returns'!AM514) -> 1.5042944 | J514: ='Daily Returns'!AT513*(1+'Daily Returns'!AN514) -> 1.3505523 | L514: ='Daily Returns'!AU513*(1+'Daily Returns'!AO514) -> 1.319252
A515: 44574 | B515: ='Daily Returns'!AP514*(1+'Daily Returns'!AK515) -> 1.504307 | D515: ='Daily Returns'!AQ514 * (1 + 'Daily Returns'!AJ515) -> 1.4420659 | F515: ='Daily Returns'!AR514 * (1 +'Daily Returns'!AL515) -> 1.4147501 | H515: ='Daily Returns'!AS514*(1+'Daily Returns'!AM515) -> 1.5066327 | J515: ='Daily Returns'!AT514*(1+'Daily Returns'!AN515) -> 1.3575692 | L515: ='Daily Returns'!AU514*(1+'Daily Returns'!AO515) -> 1.3272307
A516: 44575 | B516: ='Daily Returns'!AP515*(1+'Daily Returns'!AK516) -> 1.5050477 | D516: ='Daily Returns'!AQ515 * (1 + 'Daily Returns'!AJ516) -> 1.4432484 | F516: ='Daily Returns'!AR515 * (1 +'Daily Returns'!AL516) -> 1.3976186 | H516: ='Daily Returns'!AS515*(1+'Daily Returns'!AM516) -> 1.4845784 | J516: ='Daily Returns'!AT515*(1+'Daily Returns'!AN516) -> 1.3517907 | L516: ='Daily Returns'!AU515*(1+'Daily Returns'!AO516) -> 1.3204793
...

Sheet Weights
A1: Securities | B1: TELUS | C1: TMX GROUP LTD | D1: BARRICK GOLD | E1: VERIZON | F1: TD | G1: FREEPORT MCMORAN | H1: ROGERS | I1: RBC | J1: ANGLO AMERICAN PLC | K1: Saudi Telecom | L1: Al Rajhi Banking & Investment Corp | M1: WHEATON PRECIOUS | N1: PEPSICO | O1: ICG | P1: NUCOR CORP | Q1: COCA-COLA | R1: Great-West Lifeco Inc | S1: Riyadh Cement Co. | T1: JOHNSON&JOHNSON | U1: MANULIFE | V1: CANADIAN PACIFIC KANSAS CITY LTD | W1: PROCTOR&GAMBLE | X1: SUNLIFE | Y1: CANADIAN NATL RAILWAY CO | Z1: ENBRIDGE | AA1: RESMED | AB1: WEIR GROUP | AC1: FORTIS | AD1: NEWMONT | AE1: WASTE CONNECTIONS | AF1: EMERA INC | AG1: CVS Health Corp Bond | AH1: Canadian Treasury Bond | AI1: US Treasury Bond
A2: Weights | B2: 0.0175 | C2: 0.0375 | D2: 0.0216 | E2: 0.0175 | F2: 0.0375 | G2: 0.0216 | H2: 0.0175 | I2: 0.0375 | J2: 0.0216 | K2: 0.0175 | L2: 0.0375 | M2: 0.0216 | N2: 0.02 | O2: 0.0375 | P2: 0.0216 | Q2: 0.02 | R2: 0.0375 | S2: 0.026 | T2: 0.02 | U2: 0.0375 | V2: 0.026 | W2: 0.02 | X2: 0.0375 | Y2: 0.026 | Z2: 0.0433 | AA2: 0.01 | AB2: 0.026 | AC2: 0.0434 | AD2: 0.022 | AE2: 0.026 | AF2: 0.0433 | AG2: 0.05 | AH2: 0.05 | AI2: 0.05
A3: Total_Weight | B3: =SUM(B2:AI2) -> 1
A5: Stock Name | B5: Symbol | C5: Sector-Wise Weights | D5: Sector | F5: Rebalancing Weights of Portfolio | G5: 43921 | H5: 44012 | I5: 44104 | J5: 44196 | K5: 44286 | L5: 44377 | M5: 44469 | N5: 44561 | O5: 44651 | P5: 44742 | Q5: 44834 | R5: 44926 | S5: 45016 | T5: 45107 | U5: 45199 | V5: 45291 | W5: 45382 | X5: 45473 | Y5: 45565 | Z5: 45657
A6: TELUS COMMUNICATIONS | B6: TU | C6: 0.07 | D6: Communications | F6: TELUS | G6: 1.8534125e-20 | H6: 0.0046198144 | I6: 0.004615345 | J6: 0.0051467529 | K6: 0.024498062 | L6: 0.025582488 | M6: 0.010091637 | N6: 0.039891787 | O6: 0.020560669 | P6: 0.0041651898 | Q6: 0.019806034 | R6: 0.014452771 | S6: 0.013071273 | T6: 0.025497389 | U6: 0.017981581 | V6: 0.014886928 | W6: 0.015990104 | X6: 0.017538504 | Y6: 0.014238054 | Z6: 0.0175
A7: VERIZON COMMUNICATIONS | B7: VZ | D7: Communications | F7: VERIZON | G7: 0.02251088 | H7: 0.0097715728 | I7: 0.027800801 | J7: 0.030111115 | K7: 0.020103245 | L7: 0.022218352 | M7: 0.042013731 | N7: 0.014317318 | O7: 0.0085906808 | P7: 0.011631137 | Q7: 0.00015907992 | R7: 0.0054903897 | S7: 0.015167995 | T7: 0.0054087587 | U7: 0.014364861 | V7: 0.011864264 | W7: 0.01602261 | X7: 0.011400707 | Y7: 0.002272054 | Z7: 0.0175
A8: ROGERS COMMUNICATIONS | B8: RG | D8: Communications | F8: ROGERS | G8: 1.7212323e-20 | H8: 0.011606489 | I8: 0.00094039027 | J8: 0.0017536539 | K8: 0.005390006 | L8: 0.013050566 | M8: 0.0084442611 | N8: 0.00095076972 | O8: 0.014115225 | P8: 0.016166151 | Q8: 0.011896469 | R8: 0.0052753053 | S8: 0.0022417463 | T8: 0.013335556 | U8: 0.015323208 | V8: 0.0043665718 | W8: 0.018426341 | X8: 0.0091923514 | Y8: 0.018591485 | Z8: 0.0175
A9: SAUDI TELECOM | B9: 7010.SR | D9: Communications | F9: Saudi Telecom | G9: 0.04748912 | H9: 0.044002124 | I9: 0.036643463 | J9: 0.032988479 | K9: 0.020008687 | L9: 0.0091485946 | M9: 0.0094503705 | N9: 0.014840126 | O9: 0.026733425 | P9: 0.038037522 | Q9: 0.038138416 | R9: 0.044781534 | S9: 0.039518986 | T9: 0.025758297 | U9: 0.022330349 | V9: 0.038882236 | W9: 0.019560945 | X9: 0.031868438 | Y9: 0.034898407 | Z9: 0.0175
A10: PEPSICO INC | B10: PEP | C10: 0.08 | D10: Consumer Staples | F10: PEPSICO | G10: 3.1285885e-21 | H10: 0.019116746 | I10: 0.019422923 | J10: 0.011704172 | K10: 0.0094311468 | L10: 0.00039841495 | M10: 0.01475034 | N10: 0.013639107 | O10: 0.020911904 | P10: 0.018606553 | Q10: 0.014966165 | R10: 0.018723825 | S10: 0.020508831 | T10: 0.020101201 | U10: 0.019495407 | V10: 0.017972022 | W10: 0.0075650565 | X10: 0.018650894 | Y10: 0.020019996 | Z10: 0.02
A11: THE COCA-COLA COMPANY | B11: KO | D11: Consumer Staples | F11: COCA-COLA | G11: 0.03823761 | H11: 0.013137166 | I11: 0.017129198 | J11: 0.015823593 | K11: 0.016167723 | L11: 0.054189283 | M11: 0.0092392539 | N11: 0.016907726 | O11: 0.020137048 | P11: 0.018879908 | Q11: 0.020103627 | R11: 0.01883876 | S11: 0.024059373 | T11: 0.020732603 | U11: 0.021466545 | V11: 0.018935208 | W11: 0.015825525 | X11: 0.020942981 | Y11: 0.021262055 | Z11: 0.02
A12: JOHNSON & JOHNSON | B12: JNJ | D12: Consumer Staples | F12: JOHNSON&JOHNSON | G12: 0.04176239 | H12: 0.024728126 | I12: 0.021457721 | J12: 0.011577743 | K12: 0.033804992 | L12: 0.018851683 | M12: 0.027557466 | N12: 0.02917045 | O12: 0.021847127 | P12: 0.024886018 | Q12: 0.039743762 | R12: 0.022302766 | S12: 0.028887789 | T12: 0.01987294 | U12: 0.018017296 | V12: 0.023013955 | W12: 0.03571098 | X12: 0.019491276 | Y12: 0.019322055 | Z12: 0.02
A13: PROCTER & GAMBLE | B13: PG | D13: Consumer Staples | F13: PROCTOR&GAMBLE | G13: 0 | H13: 0.023017962 | I13: 0.021990159 | J13: 0.040894491 | K13: 0.020596138 | L13: 0.0065606188 | M13: 0.028452941 | N13: 0.020282717 | O13: 0.01710392 | P13: 0.01762752 | Q13: 0.0051864457 | R13: 0.020134649 | S13: 0.0065440067 | T13: 0.019293255 | U13: 0.021020752 | V13: 0.020078816 | W13: 0.020898439 | X13: 0.020914849 | Y13: 0.019395894 | Z13: 0.02
A14: ENBRIDGE | B14: ENB.TO | C14: 0.13 | D14: Energy | F14: ENBRIDGE | G14: 0.007520811 | H14: 0.032215864 | I14: 3.9905792e-05 | J14: 6.5292844e-20 | K14: 0.011064674 | L14: 0.014333694 | M14: 0.011444422 | N14: 0.00072751934 | O14: 0.021089504 | P14: 0.005233466 | Q14: 0.0034068688 | R14: 0.014150451 | S14: 0.031478667 | T14: 0.013955948 | U14: 0.022373152 | V14: 0.063258171 | W14: 0.034556288 | X14: 0.037164253 | Y14: 0.037324978 | Z14: 0.0433
A15: FORTIS INC | B15: FTS.TO | D15: Energy | F15: FORTIS | G15: 0.050482939 | H15: 0.032464729 | I15: 0.070434014 | J15: 0.059518916 | K15: 0.047779345 | L15: 0.037207723 | M15: 0.029729692 | N15: 0.050627126 | O15: 0.045076533 | P15: 0.047481525 | Q15: 0.043154184 | R15: 0.056601425 | S15: 0.02812988 | T15: 0.061645612 | U15: 0.028640975 | V15: 0.019622841 | W15: 0.040275683 | X15: 0.027644409 | Y15: 0.04790482 | Z15: 0.0434
A16: EMERA INC | B16: EMA.TO | D16: Energy | F16: EMERA INC | G16: 0.07199625 | H16: 0.065319406 | I16: 0.05952608 | J16: 0.070481084 | K16: 0.071155982 | L16: 0.078458583 | M16: 0.088825887 | N16: 0.078645355 | O16: 0.063833963 | P16: 0.077285009 | Q16: 0.083438948 | R16: 0.059248123 | S16: 0.070391453 | T16: 0.05439844 | U16: 0.078985873 | V16: 0.047118988 | W16: 0.055168029 | X16: 0.065191337 | Y16: 0.044770202 | Z16: 0.0433
A17: TMX GROUP LIMITED | B17: X.TO | C17: 0.3 | D17: Finance | F17: TMX GROUP LTD | G17: 0.059366689 | H17: 0.043568863 | I17: 0.089542278 | J17: 0.087989618 | K17: 0.069860413 | L17: 0.060228069 | M17: 0.051028718 | N17: 0.046295403 | O17: 0.060775551 | P17: 0.090839597 | Q17: 0.13439861 | R17: 0.067012079 | S17: 0.068842411 | T17: 0.12784608 | U17: 0.057308861 | V17: 0.061306187 | W17: 0.056586083 | X17: 0.054649539 | Y17: 0.049779804 | Z17: 0.0375
A18: TORONTO-DOMINION BANK | B18: TD.TO | D18: Finance | F18: TD | G18: 2.1148246e-20 | H18: 5.4053101e-19 | I18: 0.0075492862 | J18: 4.1821522e-19 | K18: 0.014757577 | L18: 0 | M18: 0.047721432 | N18: 0 | O18: 0 | P18: 0 | Q18: 0.021740085 | R18: 1.9736271e-18 | S18: 0.011896694 | T18: 9.5208228e-18 | U18: 0.0058540189 | V18: 0.01637807 | W18: 1.8359077e-18 | X18: 0.012417212 | Y18: 0.0088652583 | Z18: 0.0375
A19: ROYAL BANK OF CANADA | B19: RY.TO | D19: Finance | F19: RBC | G19: 0.068667106 | H19: 0.039078015 | I19: 0.031420713 | J19: 0.05348115 | K19: 0.045093332 | L19: 0.043828021 | M19: 0 | N19: 0.045972264 | O19: 0.045275858 | P19: 0.051236927 | Q19: 0.033404622 | R19: 0.025054299 | S19: 0.040178481 | T19: 4.9436433e-18 | U19: 0.024161922 | V19: 0.021312637 | W19: 0.044753496 | X19: 0.034636466 | Y19: 0.086761206 | Z19: 0.0375
A20: AL RAJHI BANKING & INVESTMENT CORP. | B20: 1120.SR | D20: Finance | F20: Al Rajhi Banking & Investment Corp | G20: 0.17196621 | H20: 0.20668829 | I20: 0.1540893 | J20: 0.1325883 | K20: 0.032809794 | L20: 0.036424567 | M20: 0.066404796 | N20: 0.026802967 | O20: 0.037146715 | P20: 0.016996875 | Q20: 0.054861669 | R20: 0.13077928 | S20: 0.045841473 | T20: 0.039030868 | U20: 0.070262328 | V20: 0.10176877 | W20: 0.0043743189 | X20: 0.057929755 | Y20: 0.10469716 | Z20: 0.0375
A21: INTERMEDIATE CAPITAL GRP | B21: ICP.L | D21: Finance | F21: ICG | G21: 1.542248e-19 | H21: 0 | I21: 0.007247556 | J21: 0 | K21: 0.022718146 | L21: 0 | M21: 0.012961841 | N21: 0.011840258 | O21: 0.010468331 | P21: 0.0043683048 | Q21: 0.019581351 | R21: 0.012743831 | S21: 0.0069468091 | T21: 0.0047423064 | U21: 0 | V21: 0.022208043 | W21: 0.01195741 | X21: 0.019690402 | Y21: 0.0088545291 | Z21: 0.0375
A22: GREAT-WEST LIFECO INC | B22: GWO.TO | D22: Finance | F22: Great-West Lifeco Inc | G22: 7.7626295e-20 | H22: 0.010664831 | I22: 0 | J22: 0.025940936 | K22: 0.08880349 | L22: 0.13274759 | M22: 0.12188321 | N22: 0.11797273 | O22: 0.1021448 | P22: 0.09984925 | Q22: 0.026525411 | R22: 0.031193198 | S22: 0.093373621 | T22: 0.072881628 | U22: 0.097175635 | V22: 0.05119647 | W22: 0.11327509 | X22: 0.078948453 | Y22: 0.037013063 | Z22: 0.0375
A23: MANULIFE | B23: MFC.TO | D23: Finance | F23: MANULIFE | G23: 0 | H23: 1.0749944e-18 | I23: 5.2177755e-19 | J23: 2.0209987e-18 | K23: 0 | L23: 0.0031163212 | M23: 0 | N23: 0.0015960684 | O23: 0.018476168 | P23: 1.1073735e-19 | Q23: 1.2125194e-18 | R23: 0.0097251947 | S23: 0.0069136758 | T23: 0.027706926 | U23: 0 | V23: 4.9487935e-20 | W23: 0.00097091465 | X23: 0.011838436 | Y23: 0 | Z23: 0.0375
A24: SUN LIFE FINANCIAL | B24: SLF.TO | D24: Finance | F24: SUNLIFE | G24: 5.0791903e-20 | H24: 3.2271399e-19 | I24: 0.010150864 | J24: 1.8157266e-18 | K24: 0.025957248 | L24: 0.023655434 | M24: 0 | N24: 0.049520311 | O24: 0.025712579 | P24: 0.036709046 | Q24: 0.0094882518 | R24: 0.023492114 | S24: 0.026006834 | T24: 0.027792196 | U24: 0.045237235 | V24: 0.025829822 | W24: 0.06808269 | X24: 0.029889738 | Y24: 0.0040289836 | Z24: 0.0375
A25: RESMED INC | B25: RMD | C25: 0.01 | D25: Medical | F25: RESMED | G25: 0.01 | H25: 0.01 | I25: 0.01 | J25: 0.01 | K25: 0.01 | L25: 0.01 | M25: 0.01 | N25: 0.01 | O25: 0.01 | P25: 0.01 | Q25: 0.01 | R25: 0.01 | S25: 0.01 | T25: 0.01 | U25: 0.01 | V25: 0.01 | W25: 0.01 | X25: 0.01 | Y25: 0.01 | Z25: 0.01
A26: NEWMONT CORP | B26: NEM | C26: 0.13 | D26: Basic Materials | F26: NEWMONT | G26: 0.00083319458 | H26: 0.034946654 | I26: 0.034364052 | J26: 0.053698322 | K26: 0.067616054 | L26: 0.053983228 | M26: 0.090490151 | N26: 0.012959888 | O26: 0.021214631 | P26: 0.051422436 | Q26: 0.01631593 | R26: 0.037054225 | S26: 0 | T26: 0.020487644 | U26: 0.040300158 | V26: 2.682935e-20 | W26: 0.008408645 | X26: 0 | Y26: 0.030358386 | Z26: 0.022
A27: BARRICK GOLD CORP | B27: ABX.TO | D27: Basic Materials | F27: BARRICK GOLD | G27: 1.0632879e-19 | H27: 0.009121397 | I27: 3.5057216e-21 | J27: 6.0421744e-21 | K27: 0 | L27: 3.3132815e-19 | M27: 0 | N27: 0.025629561 | O27: 0 | P27: 5.0420376e-19 | Q27: 0 | R27: 4.0487067e-21 | S27: 0 | T27: 0.021441428 | U27: 2.8823507e-19 | V27: 6.7712183e-20 | W27: 3.5827776e-20 | X27: 1.3367129e-21 | Y27: 0.012841495 | Z27: 0.0216
A28: FREEPORT MCMORAN B | B28: FCX | D28: Basic Materials | F28: FREEPORT MCMORAN | G28: 7.3103008e-20 | H28: 1.7711693e-21 | I28: 0.0058756988 | J28: 0.0024456224 | K28: 4.5206861e-21 | L28: 2.4969626e-20 | M28: 0 | N28: 0.0060353442 | O28: 0.014168408 | P28: 5.4003814e-20 | Q28: 0 | R28: 1.3181102e-21 | S28: 0.0047905 | T28: 0.013955762 | U28: 0.0081599445 | V28: 0 | W28: 0.012481942 | X28: 0 | Y28: 9.3723034e-21 | Z28: 0.0216
A29: ANGLO AMERICAN PLC | B29: AALL | D29: Basic Materials | F29: ANGLO AMERICAN PLC | G29: 0.036928459 | H29: 0.040242058 | I29: 0.051557166 | J29: 0.051431326 | K29: 0.028870162 | L29: 0.054274009 | M29: 0.025182571 | N29: 0.027692539 | O29: 0.052094042 | P29: 0.042909948 | Q29: 0.04362376 | R29: 0.0556744 | S29: 0.047340095 | T29: 0.026819147 | U29: 0.030909955 | V29: 0.033564035 | W29: 0.025483081 | X29: 0.019109842 | Y29: 0.058117051 | Z29: 0.0216
A30: WHEATON PRECIOUS METALS | B30: WPM | D30: Basic Materials | F30: WHEATON PRECIOUS | G30: 0.043118896 | H30: 0 | I30: 0 | J30: 6.6491357e-21 | K30: 0 | L30: 0.0083961594 | M30: 0 | N30: 0.04262707 | O30: 0.023916661 | P30: 0.014621818 | Q30: 0.049366123 | R30: 3.1066253e-21 | S30: 0.055786271 | T30: 0.021071016 | U30: 0.011179069 | V30: 0.037926401 | W30: 0.013069105 | X30: 0.055295126 | Y30: 0 | Z30: 0.0216
A31: NUCOR CORP | B31: NUE | D31: Basic Materials | F31: NUCOR CORP | G31: 0.04911945 | H31: 0.045689891 | I31: 0.038203083 | J31: 0.022424729 | K31: 0.033513784 | L31: 0.013346604 | M31: 0.014327278 | N31: 0.015055598 | O31: 0.018606258 | P31: 0.021045798 | Q31: 0.020694187 | R31: 0.037271375 | S31: 0.022083134 | T31: 0.026225004 | U31: 0.039450873 | V31: 0.058509564 | W31: 0.070557227 | X31: 0.055595032 | Y31: 0.028683068 | Z31: 0.0216
A32: RIYADH CEMENT CO. | B32: 303Q_SR | C32: 0.13 | D32: Industrial | F32: Riyadh Cement Co. | G32: 0.039098305 | H32: 0.051495365 | I32: 0.0370517 | J32: 0.057219711 | K32: 0.064576591 | L32: 0.082804549 | M32: 0.033384443 | N32: 0.046516175 | O32: 0.085326407 | P32: 0.091160686 | Q32: 0.06439044 | R32: 0.057331391 | S32: 0.030159314 | T32: 0.076157318 | U32: 0.030662344 | V32: 0.02994475 | W32: 0.074884123 | X32: 0.030505246 | Y32: 0.044897456 | Z32: 0.026
A33: CANADIAN PACIFIC KANSAS CITY LTD | B33: CP.TO | D33: Industrial | F33: CANADIAN PACIFIC KANSAS CITY LTD | G33: 0 | H33: 0.012823519 | I33: 0.0036229312 | J33: 0.015927942 | K33: 1.940146e-19 | L33: 0.0094844352 | M33: 0.022922806 | N33: 0.017393199 | O33: 0 | P33: 0.01305305 | Q33: 4.9617201e-19 | R33: 0 | S33: 0.024354832 | T33: 0.012334036 | U33: 0.022462201 | V33: 0.024975119 | W33: 0.010664472 | X33: 0.022384776 | Y33: 0.0069067488 | Z33: 0.026
A34: CANADIAN NATL RAILWAY CO | B34: CNR.TO | D34: Industrial | F34: CANADIAN NATL RAILWAY CO | G34: 0.029069656 | H34: 0.036829202 | I34: 0.049330989 | J34: 0.0043717428 | K34: 0.018614969 | L34: 0.0037845432 | M34: 0.023468355 | N34: 0.021587359 | O34: 0.019873445 | P34: 0.0015310458 | Q34: 0.025127726 | R34: 0.03612119 | S34: 0.026879204 | T34: 0.012828894 | U34: 0.02352437 | V34: 0.024157523 | W34: 0.021450661 | X34: 0.023638431 | Y34: 0.0075666391 | Z34: 0.026
A35: WEIR GROUP | B35: WEIR.L | D35: Industrial | F35: WEIR GROUP | G35: 0.0061322192 | H35: 0 | I35: 0.010824235 | J35: 0.0022361732 | K35: 0.0044695153 | L35: 0.0049088115 | M35: 0.020100648 | N35: 0.010055757 | O35: 0.0059724746 | P35: 0.0053090478 | Q35: 8.0298815e-20 | R35: 0.0065607166 | S35: 0.0215374 | T35: 0.00045303253 | U35: 0.024354787 | V35: 0.024439106 | W35: 0.0014019703 | X35: 0.024167437 | Y35: 0.01149391 | Z35: 0.026
A36: WASTE CONNECTIONS INC | B36: WCN.TO | D36: Industrial | F36: WASTE CONNECTIONS | G36: 0.05569982 | H36: 0.028851914 | I36: 0.029170145 | J36: 0.050244431 | K36: 0.042338925 | L36: 0.029017661 | M36: 0.030123748 | N36: 0.034447509 | O36: 0.018827674 | P36: 0.018946171 | Q36: 0.040481834 | R36: 0.029986702 | S36: 0.027069251 | T36: 0.028226719 | U36: 0.028996299 | V36: 0.026483501 | W36: 0.021598773 | X36: 0.02930411 | Y36: 0.059135246 | Z36: 0.026
A37: U.S. TREASURY BOND | C37: 0.15 | D37: Bonds | F37: US Treasury Bond | G37: 0.00037647067 | H37: 0.005151265 | I37: 0.0017335356 | J37: 0.0047346478 | K37: 0.010331813 | L37: 0.010408614 | M37: 0.0077156853 | N37: 0.010598661 | O37: 0.010979449 | P37: 0.014623945 | Q37: 0.020257733 | R37: 0.023244347 | S37: 0.021353969 | T37: 0.020598376 | U37: 0.026178946 | V37: 0.028087547 | W37: 0.026832919 | X37: 0.024352994 | Y37: 0.023454316 | Z37: 0.05
A38: CVS HEALTH CORP BOND | D38: Bonds | F38: CVS Health Corp Bond | G38: 0.018560216 | H38: 0.0086250838 | I38: 0.0025342171 | J38: 0 | K38: 0 | L38: 0.0026619438 | M38: 0 | N38: 0 | O38: 0 | P38: 0.0022714467 | Q38: 0.0018737499 | R38: 0.0039680838 | S38: 0.0047858478 | T38: 0.0031363155 | U38: 0.0042160091 | V38: 0.0028848905 | W38: 0.00096281174 | X38: 0 | Y38: 0 | Z38: 0.05
A39: CANADIAN TREASURY BONDS | D39: Bonds | F39: Canadian Treasury Bond | G39: 0.13106331 | H39: 0.13622365 | I39: 0.14573225 | J39: 0.14526535 | K39: 0.13966819 | L39: 0.13692944 | M39: 0.14228431 | N39: 0.13940134 | O39: 0.13902055 | P39: 0.13310461 | Q39: 0.12786852 | R39: 0.12278757 | S39: 0.12386018 | T39: 0.12626531 | U39: 0.11960504 | V39: 0.11902756 | W39: 0.12220427 | X39: 0.12564701 | Y39: 0.12654568 | Z39: 0.05
C40: =sum(C6:C39) -> 1
F42: Note on Rebalanced Portfolio Weights Calculation
...

Sheet Yearly_Metrics
A1: Year | B1: Portfolio YoY Return | C1: S&P 500 YoY Return | E1: Annually | F1: Daily
A2: 2020 | B2: {=INDEX('Daily Returns'!AP2:AP1259, MATCH(DATE(2020,12,31), 'Daily Returns'!A2:A1259, 1)) / INDEX('Daily Returns'!AP2:AP1259, MATCH(DATE(2020,1,2), 'Daily Returns'!A2:A1259, 1)) - 1} -> 0.17742126 | C2: {=INDEX('Daily Returns'!AQ2:AQ1259, MATCH(DATE(2020,12,31), 'Daily Returns'!A2:A1259, 1)) / INDEX('Daily Returns'!AQ2:AQ1259, MATCH(DATE(2020,1,2), 'Daily Returns'!A2:A1259, 1)) - 1} -> 0.15292818 | D2: Risk free rate | E2: 0.05 | F2: =(1 + E2)^(1/252) - 1 -> 0.00019363051 | G2: Considering for daily: 252 business days
A3: 2021 | B3: {=INDEX('Daily Returns'!AP2:AP1259, MATCH(DATE(2021,12,31), 'Daily Returns'!A2:A1259, 1)) / INDEX('Daily Returns'!AP2:AP1259, MATCH(DATE(2021,1,4), 'Daily Returns'!A2:A1259, 1)) - 1} -> 0.25880096 | C3: {=INDEX('Daily Returns'!AQ2:AQ1259, MATCH(DATE(2021,12,31), 'Daily Returns'!A2:A1259, 1)) / INDEX('Daily Returns'!AQ2:AQ1259, MATCH(DATE(2021,1,4), 'Daily Returns'!A2:A1259, 1)) - 1} -> 0.28792374 | G3: Risk free rate of 5% considered
A4: 2022 | B4: {=INDEX('Daily Returns'!AP2:AP1259, MATCH(DATE(2022,12,30), 'Daily Returns'!A2:A1259, 1)) / INDEX('Daily Returns'!AP2:AP1259, MATCH(DATE(2022,1,3), 'Daily Returns'!A2:A1259, 1)) - 1} -> 0.032678337 | C4: {=INDEX('Daily Returns'!AQ2:AQ1259, MATCH(DATE(2022,12,30), 'Daily Returns'!A2:A1259, 1)) / INDEX('Daily Returns'!AQ2:AQ1259, MATCH(DATE(2022,1,3), 'Daily Returns'!A2:A1259, 1)) - 1} -> -0.19953538
A5: 2023 | B5: {=INDEX('Daily Returns'!AP2:AP1259, MATCH(DATE(2023,12,29), 'Daily Returns'!A2:A1259, 1)) / INDEX('Daily Returns'!AP2:AP1259, MATCH(DATE(2023,1,3), 'Daily Returns'!A2:A1259, 1)) - 1} -> 0.066044524 | C5: {=INDEX('Daily Returns'!AQ2:AQ1259, MATCH(DATE(2023,12,29), 'Daily Returns'!A2:A1259, 1)) / INDEX('Daily Returns'!AQ2:AQ1259, MATCH(DATE(2023,1,3), 'Daily Returns'!A2:A1259, 1)) - 1} -> 0.24729015 | E5: Cumulative Portfolio | F5: S&P 500 Composite
A6: 2024 | B6: {=INDEX('Daily Returns'!AP2:AP1259, MATCH(DATE(2024,12,31), 'Daily Returns'!A2:A1259, 1)) / INDEX('Daily Returns'!AP2:AP1259, MATCH(DATE(2024,1,2), 'Daily Returns'!A2:A1259, 1)) - 1} -> 0.098453838 | C6: {=INDEX('Daily Returns'!AQ2:AQ1259, MATCH(DATE(2024,12,31), 'Daily Returns'!A2:A1259, 1)) / INDEX('Daily Returns'!AQ2:AQ1259, MATCH(DATE(2024,1,2), 'Daily Returns'!A2:A1259, 1)) - 1} -> 0.2401036 | D6: CAGR | E6: {=PRODUCT(1 + B2:B6)^(1/5) - 1} -> 0.12378241 | F6: {=PRODUCT(1 + C2:C6)^(1/5) - 1} -> 0.12951499
A7: Metric | B7: Portfolio | C7: S&P 500
A8: Beta | B8: =_xlfn.COVARIANCE.P('Daily Returns'!AK2:'Daily Returns'!AK1259, 'Daily Returns'!AJ2:'Daily Returns'!AJ1259) / VARP('Daily Returns'!AJ2:'Daily Returns'!AJ1259) -> 0.32117441 | C8: =_xlfn.COVARIANCE.P('Daily Returns'!AJ2:'Daily Returns'!AJ1259, 'Daily Returns'!AJ2:'Daily Returns'!AJ1259) / VARP('Daily Returns'!AJ2:'Daily Returns'!AJ1259) -> 1
A9: Sharpe Ratio | B9: =((AVERAGE('Daily Returns'!AK2:AK1259) - F2) / _xlfn.STDEV.P('Daily Returns'!AK2:AK1259)) * SQRT(252) -> 0.65288516 | C9: =((AVERAGE('Daily Returns'!AJ2:'Daily Returns'!AJ1259) - F2) / _xlfn.STDEV.P('Daily Returns'!AJ2:'Daily Returns'!AJ1259)) * SQRT(252) -> 0.44127809
